Workbook

Sheet Notes
A1: Notes:
A2: Quick Start Guide:
A3: 1. Add all Purchase entries first.
A4: 2. Add Sales only after item exists in Purchases.
A5: 3. Mark sale status as Completed when payment is fully received.
A6: 4. Enter settlements only when real money is exchanged.
A8: 5. Check Summary tab for final Pay/Receive for each partner.
A10: 1. Totals reference existing Purchases and Sales sheets directly.
A11: 2. Profit is only calculated on Completed sales (Status = "Completed").
A12: 3. Partner details and settlements are maintained in PartnerShares and Cash Pool sheets.
A14: 5. Cash Pool Logic:
A15: - Cash Pool shows partner contributions & withdrawals relative to each other.
... A203: 13. Profit settlement is not required when Cash Pool is regularly settled; Profit summary is kept only for FYI.

Sheet Summary
A1: Chiraath - Business Summary
A3: Total Purchases (₹) | B3: =SUM(Purchases!C:C) -> 294436 | E3: Partner | F3: Share % (Cash/Profit)
A4: Total Sales (₹ - Completed only) | B4: =SUMIFS(Sales!C:C, Sales!I:I, "Completed") -> 256492 | E4: =PartnerShares!A3 -> Rajna | F4: =PartnerShares!B3 -> 0.3334
A5: Total Sales (₹ - All rows) | B5: =SUM(Sales!C:C) -> 261022 | E5: =PartnerShares!A4 -> Anoop | F5: =PartnerShares!B4 -> 0.3332
A6: Profit / (Loss) (₹, on Completed sales only) | B6: =B4-B3 -> -37944 | E6: =PartnerShares!A5 -> Rameez | F6: =PartnerShares!B5 -> 0.3334
A7: Profit Status | B7: =IF(B6>0,"Profit","No Profit (or Loss)") -> No Profit (or Loss)
A9: Partner | B9: Net Position After Settlements (₹)
A10: Rajna | B10: =PartnerShares!H8 -> 10205.327
A11: Anoop | B11: =PartnerShares!H9 -> -4602.6633
A12: Rameez | B12: =PartnerShares!H10 -> -5602.6633
A16: Contribution Summary
A17: Partner | B17: Total Paid (₹) | C17: Target (Equal 1/3) | D17: Excess Paid (Refund Due)(₹) | E17: Settled So Far | F17: Pending Balance (+ Receive / - Pay) | G17: Action
A18: =PartnerShares!A8 -> Rajna | B18: =PartnerShares!B8 -> 126654 | C18: =PartnerShares!C8 -> 98145.333 | D18: =PartnerShares!D8 -> 28508.667 | E18: =IFERROR(SUMIFS(PartnerShares!$E$14:$E$500,PartnerShares!$D$14:$D$500,$A18,PartnerShares!$B$14:$B$500,"Contribution"),0)-IFERROR(SUMIFS(PartnerShares!$E$14:$E$500,PartnerShares!$C$14:$C$500,$A18,PartnerShares!$B$14:$B$500,"Contribution"),0) -> 18303.34 | F18: =D18-E18 -> 10205.327 | G18: =IF(ROUND(F18,0)>0,"Receive ₹"&TEXT(ABS(F18),"#,##0"),IF(ROUND(F18,0)<0,"Pay ₹"&TEXT(ABS(F18),"#,##0"),"✓ Settled")) -> Receive ₹10,205
A19: =PartnerShares!A9 -> Anoop | B19: =PartnerShares!B9 -> 135182 | C19: =PartnerShares!C9 -> 98145.333 | D19: =PartnerShares!D9 -> 37036.667 | E19: =IFERROR(SUMIFS(PartnerShares!$E$14:$E$500,PartnerShares!$D$14:$D$500,$A19,PartnerShares!$B$14:$B$500,"Contribution"),0)-IFERROR(SUMIFS(PartnerShares!$E$14:$E$500,PartnerShares!$C$14:$C$500,$A19,PartnerShares!$B$14:$B$500,"Contribution"),0) -> 41639.33 | F19: =D19-E19 -> -4602.6633 | G19: =IF(ROUND(F19,0)>0,"Receive ₹"&TEXT(ABS(F19),"#,##0"),IF(ROUND(F19,0)<0,"Pay ₹"&TEXT(ABS(F19),"#,##0"),"✓ Settled")) -> Pay ₹4,603
A20: =PartnerShares!A10 -> Rameez | B20: =PartnerShares!B10 -> 32600 | C20: =PartnerShares!C10 -> 98145.333 | D20: =PartnerShares!D10 -> -65545.333 | E20: =IFERROR(SUMIFS(PartnerShares!$E$14:$E$500,PartnerShares!$D$14:$D$500,$A20,PartnerShares!$B$14:$B$500,"Contribution"),0)-IFERROR(SUMIFS(PartnerShares!$E$14:$E$500,PartnerShares!$C$14:$C$500,$A20,PartnerShares!$B$14:$B$500,"Contribution"),0) -> -59942.67 | F20: =D20-E20 -> -5602.6633 | G20: =IF(ROUND(F20,0)>0,"Receive ₹"&TEXT(ABS(F20),"#,##0"),IF(ROUND(F20,0)<0,"Pay ₹"&TEXT(ABS(F20),"#,##0"),"✓ Settled")) -> Pay ₹5,603
A24: Cash Pool Summary
A25: Partner | B25: Cash Collected (₹) | C25: Target Cash (₹) | D25: Excess Cash Held (Debt to Pool)(₹) | E25: Cash Transferred So Far | F25: Pending Balance (+ Pay / - Receive) | G25: Action
A26: ='Cash Pool'!A4 -> Rajna | B26: ='Cash Pool'!B4 -> 235543 | C26: ='Cash Pool'!D4 -> 85514.433 | D26: ='Cash Pool'!E4 -> 150028.57 | E26: ='Cash Pool'!F4 -> -137310.03 | F26: ='Cash Pool'!G4 -> 12718.541 | G26: =IF(ROUND(F26,0)>0,"Pay ₹"&TEXT(ABS(F26),"#,##0"),IF(ROUND(F26,0)<0,"Receive ₹"&TEXT(ABS(F26),"#,##0"),"✓ Settled")) -> Pay ₹12,719
A27: ='Cash Pool'!A5 -> Anoop | B27: ='Cash Pool'!B5 -> 8419 | C27: ='Cash Pool'!D5 -> 85463.134 | D27: ='Cash Pool'!E5 -> -77044.134 | E27: ='Cash Pool'!F5 -> 71587.042 | F27: ='Cash Pool'!G5 -> -5457.0924 | G27: =IF(ROUND(F27,0)>0,"Pay ₹"&TEXT(ABS(F27),"#,##0"),IF(ROUND(F27,0)<0,"Receive ₹"&TEXT(ABS(F27),"#,##0"),"✓ Settled")) -> Receive ₹5,457
A28: ='Cash Pool'!A6 -> Rameez | B28: ='Cash Pool'!B6 -> 12530 | C28: ='Cash Pool'!D6 -> 85514.433 | D28: ='Cash Pool'!E6 -> -72984.433 | E28: ='Cash Pool'!F6 -> 65722.984 | F28: ='Cash Pool'!G6 -> -7261.4488 | G28: =IF(ROUND(F28,0)>0,"Pay ₹"&TEXT(ABS(F28),"#,##0"),IF(ROUND(F28,0)<0,"Receive ₹"&TEXT(ABS(F28),"#,##0"),"✓ Settled")) -> Receive ₹7,261
A32: Profit Summary
A33: Partner | B33: Profit Share (₹)
A34: =PartnerShares!A8 -> Rajna | B34: =PartnerShares!E8 -> 0
A35: =PartnerShares!A9 -> Anoop | B35: =PartnerShares!E9 -> 0
A36: =PartnerShares!A10 -> Rameez | B36: =PartnerShares!E10 -> 0

Sheet Dashboard
A1: Chiraath Boutique – Business Dashboard
A3: Last Updated | B3: =TODAY() -> 46123
A5: Total Purchases (₹) | B5: =Summary!B3 -> 294436 | D5: Total Sales (₹ - Completed) | E5: =Summary!B4 -> 256492
A6: Total Profit (₹) | B6: =Summary!B6 -> -37944 | D6: Pending Stock Value (₹) | E6: =SUMIFS(INVENTORY!K:K, INVENTORY!N:N, "<>Sold Out") -> 112204.07
A7: Filter Year: | B7: 2026
A9: Month | B9: Purchases (₹) | C9: Sales (₹) | D9: Net Cash Flow (₹) | F9: Metric | G9: Qty
A10: Jan | B10: =IFERROR(SUMPRODUCT((TEXT(Purchases!$A$2:$A$998,"MMM")=$A10)*(YEAR(Purchases!$A$2:$A$998)=$B$7)*Purchases!$C$2:$C$998),0) -> 47311 | C10: =IFERROR(SUMPRODUCT((TEXT(Sales!$A$2:$A$997,"MMM")=$A10)*(YEAR(Sales!$A$2:$A$997)=$B$7)*Sales!$C$2:$C$997),0) -> 45448 | D10: =C10-B10 -> -1863 | F10: Qty Sold | G10: =SUM(INVENTORY!F:F) -> 207
A11: Feb | B11: =IFERROR(SUMPRODUCT((TEXT(Purchases!$A$2:$A$998,"MMM")=$A11)*(YEAR(Purchases!$A$2:$A$998)=$B$7)*Purchases!$C$2:$C$998),0) -> 4790 | C11: =IFERROR(SUMPRODUCT((TEXT(Sales!$A$2:$A$997,"MMM")=$A11)*(YEAR(Sales!$A$2:$A$997)=$B$7)*Sales!$C$2:$C$997),0) -> 19089 | D11: =C11-B11 -> 14299 | F11: Qty Pending | G11: =SUM(INVENTORY!G:G) -> 127
A12: Mar | B12: =IFERROR(SUMPRODUCT((TEXT(Purchases!$A$2:$A$998,"MMM")=$A12)*(YEAR(Purchases!$A$2:$A$998)=$B$7)*Purchases!$C$2:$C$998),0) -> 22172 | C12: =IFERROR(SUMPRODUCT((TEXT(Sales!$A$2:$A$997,"MMM")=$A12)*(YEAR(Sales!$A$2:$A$997)=$B$7)*Sales!$C$2:$C$997),0) -> 16548 | D12: =C12-B12 -> -5624
A13: Apr | B13: =IFERROR(SUMPRODUCT((TEXT(Purchases!$A$2:$A$998,"MMM")=$A13)*(YEAR(Purchases!$A$2:$A$998)=$B$7)*Purchases!$C$2:$C$998),0) -> 15145 | C13: =IFERROR(SUMPRODUCT((TEXT(Sales!$A$2:$A$997,"MMM")=$A13)*(YEAR(Sales!$A$2:$A$997)=$B$7)*Sales!$C$2:$C$997),0) -> 13910 | D13: =C13-B13 -> -1235
A14: May | B14: =IFERROR(SUMPRODUCT((TEXT(Purchases!$A$2:$A$998,"MMM")=$A14)*(YEAR(Purchases!$A$2:$A$998)=$B$7)*Purchases!$C$2:$C$998),0) -> 0 | C14: =IFERROR(SUMPRODUCT((TEXT(Sales!$A$2:$A$997,"MMM")=$A14)*(YEAR(Sales!$A$2:$A$997)=$B$7)*Sales!$C$2:$C$997),0) -> 0 | D14: =C14-B14 -> 0
A15: Jun | B15: =IFERROR(SUMPRODUCT((TEXT(Purchases!$A$2:$A$998,"MMM")=$A15)*(YEAR(Purchases!$A$2:$A$998)=$B$7)*Purchases!$C$2:$C$998),0) -> 0 | C15: =IFERROR(SUMPRODUCT((TEXT(Sales!$A$2:$A$997,"MMM")=$A15)*(YEAR(Sales!$A$2:$A$997)=$B$7)*Sales!$C$2:$C$997),0) -> 0 | D15: =C15-B15 -> 0
A16: Jul | B16: =IFERROR(SUMPRODUCT((TEXT(Purchases!$A$2:$A$998,"MMM")=$A16)*(YEAR(Purchases!$A$2:$A$998)=$B$7)*Purchases!$C$2:$C$998),0) -> 0 | C16: =IFERROR(SUMPRODUCT((TEXT(Sales!$A$2:$A$997,"MMM")=$A16)*(YEAR(Sales!$A$2:$A$997)=$B$7)*Sales!$C$2:$C$997),0) -> 0 | D16: =C16-B16 -> 0
A17: Aug | B17: =IFERROR(SUMPRODUCT((TEXT(Purchases!$A$2:$A$998,"MMM")=$A17)*(YEAR(Purchases!$A$2:$A$998)=$B$7)*Purchases!$C$2:$C$998),0) -> 0 | C17: =IFERROR(SUMPRODUCT((TEXT(Sales!$A$2:$A$997,"MMM")=$A17)*(YEAR(Sales!$A$2:$A$997)=$B$7)*Sales!$C$2:$C$997),0) -> 0 | D17: =C17-B17 -> 0
A18: Sep | B18: =IFERROR(SUMPRODUCT((TEXT(Purchases!$A$2:$A$998,"MMM")=$A18)*(YEAR(Purchases!$A$2:$A$998)=$B$7)*Purchases!$C$2:$C$998),0) -> 0 | C18: =IFERROR(SUMPRODUCT((TEXT(Sales!$A$2:$A$997,"MMM")=$A18)*(YEAR(Sales!$A$2:$A$997)=$B$7)*Sales!$C$2:$C$997),0) -> 0 | D18: =C18-B18 -> 0
A19: Oct | B19: =IFERROR(SUMPRODUCT((TEXT(Purchases!$A$2:$A$998,"MMM")=$A19)*(YEAR(Purchases!$A$2:$A$998)=$B$7)*Purchases!$C$2:$C$998),0) -> 0 | C19: =IFERROR(SUMPRODUCT((TEXT(Sales!$A$2:$A$997,"MMM")=$A19)*(YEAR(Sales!$A$2:$A$997)=$B$7)*Sales!$C$2:$C$997),0) -> 0 | D19: =C19-B19 -> 0
A20: Nov | B20: =IFERROR(SUMPRODUCT((TEXT(Purchases!$A$2:$A$998,"MMM")=$A20)*(YEAR(Purchases!$A$2:$A$998)=$B$7)*Purchases!$C$2:$C$998),0) -> 0 | C20: =IFERROR(SUMPRODUCT((TEXT(Sales!$A$2:$A$997,"MMM")=$A20)*(YEAR(Sales!$A$2:$A$997)=$B$7)*Sales!$C$2:$C$997),0) -> 0 | D20: =C20-B20 -> 0
A21: Dec | B21: =IFERROR(SUMPRODUCT((TEXT(Purchases!$A$2:$A$998,"MMM")=$A21)*(YEAR(Purchases!$A$2:$A$998)=$B$7)*Purchases!$C$2:$C$998),0) -> 0 | C21: =IFERROR(SUMPRODUCT((TEXT(Sales!$A$2:$A$997,"MMM")=$A21)*(YEAR(Sales!$A$2:$A$997)=$B$7)*Sales!$C$2:$C$997),0) -> 0 | D21: =C21-B21 -> 0
F46: Category | G46: Qty Sold | H46: Qty Pending | J46: Category | K46: Pending Value (₹)
F47: Saree | G47: =SUMIF(INVENTORY!C:C, F47, INVENTORY!F:F) -> 129 | H47: =SUMIF(INVENTORY!C:C, F47, INVENTORY!G:G) -> 54 | J47: Salwar | K47: {=SUMPRODUCT((INVENTORY!$C$2:$C$477=J47)*(INVENTORY!$D$2:$D$477)*(INVENTORY!$G$2:$G$477))} -> 69946
F48: Salwar | G48: =SUMIF(INVENTORY!C:C, F48, INVENTORY!F:F) -> 76 | H48: =SUMIF(INVENTORY!C:C, F48, INVENTORY!G:G) -> 68 | J48: Saree | K48: {=SUMPRODUCT((INVENTORY!$C$2:$C$477=J48)*(INVENTORY!$D$2:$D$477)*(INVENTORY!$G$2:$G$477))} -> 41509.067
F49: Kurti | G49: =SUMIF(INVENTORY!C:C, F49, INVENTORY!F:F) -> 2 | H49: =SUMIF(INVENTORY!C:C, F49, INVENTORY!G:G) -> 5 | J49: Kurti | K49: {=SUMPRODUCT((INVENTORY!$C$2:$C$477=J49)*(INVENTORY!$D$2:$D$477)*(INVENTORY!$G$2:$G$477))} -> 1829

Sheet Purchases
A1: Date | B1: Partner | C1: Amount (₹) | D1: Notes
A2: 45890 | B2: Rameez | C2: 10650 | D2: Initial contribution
A3: 45890 | B3: Rajna | C3: 55219 | D3: Initial contribution (Anoop transferered 35k)
A4: 45897 | B4: Anoop | C4: 35000 | D4: Initial contribution
A5: 45908 | B5: Rajna | C5: 1250 | D5: Davani for Priya
A6: 45908 | B6: Rajna | C6: 75 | D6: Kannur courier
A7: 45922 | B7: Rameez | C7: 199 | D7: Recharge
A8: 45922 | B8: Rajna | C8: 200 | D8: Courier cover
A9: 45922 | B9: Rajna | C9: 350 | D9: Courier Assam
A10: 45922 | B10: Rajna | C10: 230 | D10: Courier Assam
A11: 45931 | B11: Anoop | C11: 35750 | D11: New purchases Salwars
A12: 45931 | B12: Rajna | C12: 1362 | D12: New purchases Salwars
A13: 45931 | B13: Rajna | C13: 450 | D13: Cotton Saree
... A62: 46122 | B62: Rajna | C62: 166 | D62: Postal charges

Sheet Sales
A1: Date | B1: Customer | C1: Amount (₹) | D1: Payment Method | E1: Partner Received | F1: Size | G1: Color | H1: Comments | I1: Status
A2: 45900 | B2: Chris | C2: 1250 | D2: GPay | E2: Rajna | I2: Completed
A3: 45900 | B3: Susmitha | C3: 1600 | D3: Cash | E3: Rajna | I3: Completed
A4: 45900 | B4: Jisha | C4: 1800 | D4: Cash | E4: Rajna | I4: Completed
A5: 45900 | B5: Sreejesh | C5: 2000 | D5: GPay | E5: Rajna | I5: Completed
A6: 45900 | B6: Latha | C6: 1600 | D6: Cash | E6: Rajna | I6: Completed
A7: 45900 | B7: Beena (Knr) | C7: 750 | D7: GPay | E7: Rajna | I7: Completed
A8: 45900 | B8: Binoy | C8: 3600 | D8: GPay | E8: Rajna | I8: Completed
A9: 45901 | B9: Binoy | C9: 1000 | D9: GPay | E9: Rajna | I9: Completed
A10: 45902 | B10: Suresh (PVB) | C10: 2000 | D10: GPay | E10: Rajna | I10: Completed
A11: 45903 | B11: Raji | C11: 3400 | D11: GPay | E11: Rajna | I11: Completed
A12: 45904 | B12: Divya | C12: 2500 | D12: Karassery Bank | E12: Rajna | I12: Completed
A13: 45905 | B13: Munni | C13: 4000 | D13: GPay | E13: Rajna | I13: Completed
... A53: 45985 | B53: Aasa | C53: 1600 | D53: Gpay | E53: Rajna | I53: Completed
A54: 45986 | B54: Shimna | C54: 4900 | D54: Gpay | E54: Rajna | H54: Anchal 3 salwars | I54: Completed
A55: 45992 | B55: Yaaser | C55: 4500 | D55: Gpay | E55: Rajna | H55: Anchal 3 salwars | I55: Completed
A56: 45992 | B56: Shanu | C56: 1600 | D56: Gpay | E56: Rajna | H56: Chanderi silk salwar | I56: Completed
A57: 45996 | B57: Ranju | C57: 1500 | D57: Gpay | E57: Rajna | H57: Black Salwar (XXL) | I57: Completed
A58: 45996 | B58: Aruna | C58: 7500 | D58: Gpay | E58: Rajna | H58: Silk Saree, Kalyani yellow saree, Banarasi biscuit, Banarasi blue, Pashmina saree, Chanderi violet saree | I58: Completed
A59: 45996 | B59: Malini | C59: 1400 | D59: Cash | E59: Rajna | H59: Banarasi Chikku | I59: Completed
A60: 46007 | B60: Resmi | C60: 699 | D60: Net banking | E60: Rajna | H60: Chanderi blue saree | I60: Completed
A61: 46008 | B61: Jisha | C61: 1400 | D61: Karassery Account | E61: Rajna | F61: L | H61: Maroon - Silk Blend Salwar set | I61: Completed
A62: 46008 | B62: Rishma | C62: 1380 | D62: Gpay | E62: Rajna | H62: Yellow Banarasi | I62: Completed
A63: 46008 | B63: Aasa | C63: 1380 | D63: Gpay | E63: Rajna | H63: Yellow/Green Banarasi | I63: Completed
A64: 46008 | B64: Malini | C64: 700 | D64: Gpay | E64: Rajna | H64: Chanderi rani pink saree | I64: Completed
A65: 46009 | B65: Dona | C65: 2100 | D65: Cash | E65: Rajna | H65: Aanchal green floral & Silk Saree | I65: Completed
A66: 46010 | B66: Jyothi mol | C66: 1380 | D66: Karassery Account | E66: Rajna | H66: Yellow/Green Banarasi | I66: Completed
A67: 46010 | B67: Prema | C67: 1000 | D67: Gpay | E67: Rajna | F67: XXL | H67: Brick Red Salwar Elephant print | I67: Completed
A68: 46011 | B68: Sruthi | C68: 3900 | D68: Gpay | E68: Rajna | H68: Anchal Off white/blue dupatta salwar, red wine salwar, Anchal black salwar | I68: Completed
A69: 46011 | B69: Nalini | C69: 1400 | D69: Gpay | E69: Rajna | H69: Tie & Dye Rani Pink | I69: Completed
A70: 46011 | B70: Anoop | C70: 1400 | D70: Cash | E70: Anoop | H70: gift(Khadi/Salwars) - White violet salwar, Khadi | I70: Completed
A71: 46011 | B71: Ranju | C71: 1400 | D71: Cash | E71: Rajna | H71: gift(Khadi/Salwars) - Khadi | I71: Completed
A72: 46011 | B72: Girija | C72: 3700 | D72: Gpay | E72: Rajna | H72: Viscose Rayan Saree, Banarasi Chikku green, Khadi, Rayon multi colored Salwar(XL) | I72: Completed
A73: 46011 | B73: Malu | C73: 4529 | D73: Cash | E73: Anoop | H73: Golden Banarasi, Cotton Silk (contrast colors), Kalyani Cotton Orange | I73: Completed
A74: 46013 | B74: Sourabhya | C74: 580 | D74: Gpay | E74: Rajna | F74: XL | H74: Jute Kurti | I74: Completed
A75: 46013 | B75: Shajeena (TVM) | C75: 1380 | D75: Gpay | E75: Rajna | H75: Banarasi Chikku | I75: Completed
A76: 46017 | B76: Vijina (Kannur) | C76: 1380 | D76: Gpay | E76: Rajna | H76: Banarasi Golden Yellow | I76: Completed
A77: 46017 | B77: Nisha Nair (Alappuzha) | C77: 1380 | D77: Gpay | E77: Rajna | H77: Parrot Green Banarasi | I77: Completed
A78: 46017 | B78: Silpa | C78: 690 | D78: Cash | E78: Rajna | H78: Banarasi Saree - Biscuit | I78: Completed
A79: 46017 | B79: Silpa | C79: 690 | D79: Cash | E79: Anoop | H79: Banarasi Saree - Biscuit | I79: Completed
...

Sheet INVENTORY
A1: SKU | B1: Item Name | C1: Category | D1: Purchase Price (₹) | E1: Sale Amount (₹) | F1: Qty Sold | G1: Qty Pending | H1: Qty Purchased | I1: Cost per Item (₹) | J1: Cost of Sold (₹) | K1: Stock Value (₹) | L1: Buyer | M1: Partner Received | N1: Status | O1: Size | P1: Color | Q1: Comments | R1: Brand | S1: Material | T1: Discount
A2: CHR-1 | B2: Black Saree | C2: Saree | D2: 779 | E2: 1250 | F2: 1 | G2: 0 | H2: =F2+IF(LEN(G2)=0,0,G2) -> 1 | I2: =IF(D2<>"",D2,IFERROR(E2/(IFERROR(SUM(Sales!C:C),0))*(IFERROR(SUM(Purchases!C:C),0)),0)) -> 779 | J2: =F2*I2 -> 779 | K2: =IF(LEN(G2)=0,0,G2)*I2 -> 0 | L2: Chris | M2: Rajna | N2: Sold Out
A3: CHR-2 | B3: Imported Rayon Salwar Black | C3: Saree | D3: 1096 | E3: 1600 | F3: 1 | G3: 0 | H3: =F3+IF(LEN(G3)=0,0,G3) -> 1 | I3: =IF(D3<>"",D3,IFERROR(E3/(IFERROR(SUM(Sales!C:C),0))*(IFERROR(SUM(Purchases!C:C),0)),0)) -> 1096 | J3: =F3*I3 -> 1096 | K3: =IF(LEN(G3)=0,0,G3)*I3 -> 0 | L3: Susmitha | M3: Rajna | N3: Sold Out
A4: CHR-3 | B4: Cotton Silk | C4: Saree | D4: 1048 | E4: 2000 | F4: 1 | G4: 0 | H4: =F4+IF(LEN(G4)=0,0,G4) -> 1 | I4: =IF(D4<>"",D4,IFERROR(E4/(IFERROR(SUM(Sales!C:C),0))*(IFERROR(SUM(Purchases!C:C),0)),0)) -> 1048 | J4: =F4*I4 -> 1048 | K4: =IF(LEN(G4)=0,0,G4)*I4 -> 0 | L4: Sreejesh | M4: Rajna | N4: Sold Out
A5: CHR-4 | B5: Silk Saree | C5: Saree | D5: 887 | E5: 1600 | F5: 1 | G5: 0 | H5: =F5+IF(LEN(G5)=0,0,G5) -> 1 | I5: =IF(D5<>"",D5,IFERROR(E5/(IFERROR(SUM(Sales!C:C),0))*(IFERROR(SUM(Purchases!C:C),0)),0)) -> 887 | J5: =F5*I5 -> 887 | K5: =IF(LEN(G5)=0,0,G5)*I5 -> 0 | L5: Latha | M5: Rajna | N5: Sold Out
A6: CHR-5 | B6: Light weight cotton | C6: Saree | D6: 372 | E6: 750 | F6: 1 | G6: 0 | H6: =F6+IF(LEN(G6)=0,0,G6) -> 1 | I6: =IF(D6<>"",D6,IFERROR(E6/(IFERROR(SUM(Sales!C:C),0))*(IFERROR(SUM(Purchases!C:C),0)),0)) -> 372 | J6: =F6*I6 -> 372 | K6: =IF(LEN(G6)=0,0,G6)*I6 -> 0 | L6: Beena (Knr), Sudhisha | M6: Rajna | N6: Sold Out
A7: CHR-6 | B7: Saree USA print (step photo) | C7: Saree | D7: 625 | E7: 1000 | F7: 1 | G7: 0 | H7: =F7+IF(LEN(G7)=0,0,G7) -> 1 | I7: =IF(D7<>"",D7,IFERROR(E7/(IFERROR(SUM(Sales!C:C),0))*(IFERROR(SUM(Purchases!C:C),0)),0)) -> 625 | J7: =F7*I7 -> 625 | K7: =IF(LEN(G7)=0,0,G7)*I7 -> 0 | L7: Binoy | M7: Rajna | N7: Sold Out
A8: CHR-7 | B8: Saree 95 1 | C8: Saree | D8: 1559 | E8: 2600 | F8: 1 | G8: 0 | H8: =F8+IF(LEN(G8)=0,0,G8) -> 1 | I8: =IF(D8<>"",D8,IFERROR(E8/(IFERROR(SUM(Sales!C:C),0))*(IFERROR(SUM(Purchases!C:C),0)),0)) -> 1559 | J8: =F8*I8 -> 1559 | K8: =IF(LEN(G8)=0,0,G8)*I8 -> 0 | L8: Binoy | M8: Rajna | N8: Sold Out
A9: CHR-8 | B9: Linen Block Print Salwar Set | C9: Salwar | D9: 839 | E9: 1000 | F9: 1 | G9: 0 | H9: =F9+IF(LEN(G9)=0,0,G9) -> 1 | I9: =IF(D9<>"",D9,IFERROR(E9/(IFERROR(SUM(Sales!C:C),0))*(IFERROR(SUM(Purchases!C:C),0)),0)) -> 839 | J9: =F9*I9 -> 839 | K9: =IF(LEN(G9)=0,0,G9)*I9 -> 0 | L9: Binoy | M9: Rajna | N9: Sold Out
A10: CHR-9 | B10: Cotton Silk | C10: Saree | D10: 1148 | E10: 2000 | F10: 1 | G10: 0 | H10: =F10+IF(LEN(G10)=0,0,G10) -> 1 | I10: =IF(D10<>"",D10,IFERROR(E10/(IFERROR(SUM(Sales!C:C),0))*(IFERROR(SUM(Purchases!C:C),0)),0)) -> 1148 | J10: =F10*I10 -> 1148 | K10: =IF(LEN(G10)=0,0,G10)*I10 -> 0 | L10: Suresh (PVB) | M10: Rajna | N10: Sold Out
A11: CHR-10 | B11: Black red banarasi | C11: Saree | D11: 1252 | E11: 1800 | F11: 2 | G11: 0 | H11: =F11+IF(LEN(G11)=0,0,G11) -> 2 | I11: =IF(D11<>"",D11,IFERROR(E11/(IFERROR(SUM(Sales!C:C),0))*(IFERROR(SUM(Purchases!C:C),0)),0)) -> 1252 | J11: =F11*I11 -> 2504 | K11: =IF(LEN(G11)=0,0,G11)*I11 -> 0 | L11: Raji, Jisha | M11: Rajna | N11: Sold Out
A12: CHR-11 | B12: Black Imported Rayon Set | C12: Salwar | D12: 1096 | E12: 1600 | F12: 1 | G12: 0 | H12: =F12+IF(LEN(G12)=0,0,G12) -> 1 | I12: =IF(D12<>"",D12,IFERROR(E12/(IFERROR(SUM(Sales!C:C),0))*(IFERROR(SUM(Purchases!C:C),0)),0)) -> 1096 | J12: =F12*I12 -> 1096 | K12: =IF(LEN(G12)=0,0,G12)*I12 -> 0 | L12: Raji | M12: Rajna | N12: Sold Out
A13: CHR-12 | B13: Imported Rayon Salwar Set Red | C13: Salwar | D13: 1096 | E13: 1600 | F13: 1 | G13: 0 | H13: =F13+IF(LEN(G13)=0,0,G13) -> 1 | I13: =IF(D13<>"",D13,IFERROR(E13/(IFERROR(SUM(Sales!C:C),0))*(IFERROR(SUM(Purchases!C:C),0)),0)) -> 1096 | J13: =F13*I13 -> 1096 | K13: =IF(LEN(G13)=0,0,G13)*I13 -> 0 | L13: Divya | M13: Rajna | N13: Sold Out
... A43: CHR-42 | B43: Linen Floral Salwar Set (sunflower) | C43: Salwar | D43: 839 | E43: 950 | F43: 1 | G43: 0 | H43: =F43+IF(LEN(G43)=0,0,G43) -> 1 | I43: =IF(D43<>"",D43,IFERROR(E43/(IFERROR(SUM(Sales!C:C),0))*(IFERROR(SUM(Purchases!C:C),0)),0)) -> 839 | J43: =F43*I43 -> 839 | K43: =IF(LEN(G43)=0,0,G43)*I43 -> 0 | L43: Yassar | M43: Rajna | N43: Sold Out
A44: CHR-43 | B44: Black Soft Cotton Flared Salwar Set | C44: Salwar | D44: 1165 | E44: 1500 | F44: 2 | G44: 0 | H44: =F44+IF(LEN(G44)=0,0,G44) -> 2 | I44: =IF(D44<>"",D44,IFERROR(E44/(IFERROR(SUM(Sales!C:C),0))*(IFERROR(SUM(Purchases!C:C),0)),0)) -> 1165 | J44: =F44*I44 -> 2330 | K44: =IF(LEN(G44)=0,0,G44)*I44 -> 0 | L44: Anju, Ranju | M44: Rajna | N44: Sold Out | O44: XXL | Q44: XXL pending
A45: CHR-44 | B45: Green & black cotton silk | C45: Saree | D45: 1048 | E45: 1900 | F45: 1 | G45: 0 | H45: =F45+IF(LEN(G45)=0,0,G45) -> 1 | I45: =IF(D45<>"",D45,IFERROR(E45/(IFERROR(SUM(Sales!C:C),0))*(IFERROR(SUM(Purchases!C:C),0)),0)) -> 1048 | J45: =F45*I45 -> 1048 | K45: =IF(LEN(G45)=0,0,G45)*I45 -> 0 | L45: Anju | M45: Rajna | N45: Sold Out
A46: CHR-45 | B46: Cotton Peach | C46: Saree | D46: 372 | E46: 650 | F46: 1 | G46: 0 | H46: =F46+IF(LEN(G46)=0,0,G46) -> 1 | I46: =IF(D46<>"",D46,IFERROR(E46/(IFERROR(SUM(Sales!C:C),0))*(IFERROR(SUM(Purchases!C:C),0)),0)) -> 372 | J46: =F46*I46 -> 372 | K46: =IF(LEN(G46)=0,0,G46)*I46 -> 0 | L46: Anju | M46: Rajna | N46: Sold Out
A47: CHR-46 | B47: Tusser embroidary saress | C47: Saree | D47: 1094 | E47: 1400 | F47: 4 | G47: 1 | H47: =F47+IF(LEN(G47)=0,0,G47) -> 5 | I47: =IF(D47<>"",D47,IFERROR(E47/(IFERROR(SUM(Sales!C:C),0))*(IFERROR(SUM(Purchases!C:C),0)),0)) -> 1094 | J47: =F47*I47 -> 4376 | K47: =IF(LEN(G47)=0,0,G47)*I47 -> 1094 | L47: Anju, Annie(2-blue/green) | M47: Rajna/Rameez | N47: Partially Sold
A48: CHR-47 | B48: Mal Chanderi | C48: Saree | D48: 779 | E48: 1000 | F48: 1 | G48: 0 | H48: =F48+IF(LEN(G48)=0,0,G48) -> 1 | I48: =IF(D48<>"",D48,IFERROR(E48/(IFERROR(SUM(Sales!C:C),0))*(IFERROR(SUM(Purchases!C:C),0)),0)) -> 779 | J48: =F48*I48 -> 779 | K48: =IF(LEN(G48)=0,0,G48)*I48 -> 0 | L48: Anju | M48: Rajna | N48: Sold Out
A49: CHR-48 | B49: Pink Tussar Emb | C49: Saree | D49: 895 | E49: 1400 | F49: 1 | G49: 0 | H49: =F49+IF(LEN(G49)=0,0,G49) -> 1 | I49: =IF(D49<>"",D49,IFERROR(E49/(IFERROR(SUM(Sales!C:C),0))*(IFERROR(SUM(Purchases!C:C),0)),0)) -> 895 | J49: =F49*I49 -> 895 | K49: =IF(LEN(G49)=0,0,G49)*I49 -> 0 | L49: Anju | M49: Rajna | N49: Sold Out | P49: Pink
A50: CHR-49 | B50: Soft Cotton Salwar set - wine red | C50: Salwar | D50: 1145 | E50: 1400 | F50: 1 | G50: 0 | H50: =F50+IF(LEN(G50)=0,0,G50) -> 1 | I50: =IF(D50<>"",D50,IFERROR(E50/(IFERROR(SUM(Sales!C:C),0))*(IFERROR(SUM(Purchases!C:C),0)),0)) -> 1145 | J50: =F50*I50 -> 1145 | K50: =IF(LEN(G50)=0,0,G50)*I50 -> 0 | L50: Rameez | M50: Rajna | N50: Sold Out
A51: CHR-50 | B51: Black Soft Cotton Flared Salwar Set | C51: Salwar | D51: 1165 | E51: 1400 | F51: 1 | G51: 0 | H51: =F51+IF(LEN(G51)=0,0,G51) -> 1 | I51: =IF(D51<>"",D51,IFERROR(E51/(IFERROR(SUM(Sales!C:C),0))*(IFERROR(SUM(Purchases!C:C),0)),0)) -> 1165 | J51: =F51*I51 -> 1165 | K51: =IF(LEN(G51)=0,0,G51)*I51 -> 0 | L51: Rameez | M51: Rajna | N51: Sold Out
A52: CHR-51 | B52: Mull Cotton Floral print with lace detailing | C52: Salwar | D52: 1200 | E52: 799 | F52: 1 | G52: 3 | H52: =F52+IF(LEN(G52)=0,0,G52) -> 4 | I52: =IF(D52<>"",D52,IFERROR(E52/(IFERROR(SUM(Sales!C:C),0))*(IFERROR(SUM(Purchases!C:C),0)),0)) -> 1200 | J52: =F52*I52 -> 1200 | K52: =IF(LEN(G52)=0,0,G52)*I52 -> 3600 | L52: Jiji | N52: Partially Sold | O52: M, L, XXL | P52: Red
A53: CHR-52 | B53: Chanderi Soft Silk Salwar Set | C53: Salwar | D53: 1941 | E53: 1250 | F53: 2 | G53: 1 | H53: =F53+IF(LEN(G53)=0,0,G53) -> 3 | I53: =IF(D53<>"",D53,IFERROR(E53/(IFERROR(SUM(Sales!C:C),0))*(IFERROR(SUM(Purchases!C:C),0)),0)) -> 1941 | J53: =F53*I53 -> 3882 | K53: =IF(LEN(G53)=0,0,G53)*I53 -> 1941 | L53: Shanu - 1800, Rinsha friend - 1000 | N53: Pending | O53: XL | P53: Ocean Blue
A54: CHR-53 | B54: Hakoba Cotton Chridar | C54: Salwar | D54: 1476 | E54: 1600 | F54: 0 | G54: 2 | H54: =F54+IF(LEN(G54)=0,0,G54) -> 2 | I54: =IF(D54<>"",D54,IFERROR(E54/(IFERROR(SUM(Sales!C:C),0))*(IFERROR(SUM(Purchases!C:C),0)),0)) -> 1476 | J54: =F54*I54 -> 0 | K54: =IF(LEN(G54)=0,0,G54)*I54 -> 2952 | N54: Pending | O54: L | P54: Blue, Black | Q54: Returned
A55: CHR-54 | B55: Linen Floral Print Salwar Set | C55: Salwar | D55: 995 | E55: 1000 | F55: 1 | G55: 1 | H55: =F55+IF(LEN(G55)=0,0,G55) -> 2 | I55: =IF(D55<>"",D55,IFERROR(E55/(IFERROR(SUM(Sales!C:C),0))*(IFERROR(SUM(Purchases!C:C),0)),0)) -> 995 | J55: =F55*I55 -> 995 | K55: =IF(LEN(G55)=0,0,G55)*I55 -> 995 | L55: Sruthi(M) | M55: Rajna | N55: Partially Sold | O55: L
A56: CHR-55 | B56: Linen Block Print Salwar Set | C56: Salwar | D56: 839 | E56: 1000 | F56: 1 | G56: 0 | H56: =F56+IF(LEN(G56)=0,0,G56) -> 1 | I56: =IF(D56<>"",D56,IFERROR(E56/(IFERROR(SUM(Sales!C:C),0))*(IFERROR(SUM(Purchases!C:C),0)),0)) -> 839 | J56: =F56*I56 -> 839 | K56: =IF(LEN(G56)=0,0,G56)*I56 -> 0 | L56: Rameez | M56: Rajna | N56: Sold Out | O56: XL-XXL
A57: CHR-56 | B57: Pakistani Semi Silk Blend | C57: Salwar | D57: 1095 | E57: 1400 | F57: 0 | G57: 3 | H57: =F57+IF(LEN(G57)=0,0,G57) -> 3 | I57: =IF(D57<>"",D57,IFERROR(E57/(IFERROR(SUM(Sales!C:C),0))*(IFERROR(SUM(Purchases!C:C),0)),0)) -> 1095 | J57: =F57*I57 -> 0 | K57: =IF(LEN(G57)=0,0,G57)*I57 -> 3285 | N57: Pending | O57: M-XL
A58: CHR-57 | B58: Linen Floral Salwar Set (yellow) | C58: Salwar | D58: 839 | E58: 1000 | F58: 0 | G58: 2 | H58: =F58+IF(LEN(G58)=0,0,G58) -> 2 | I58: =IF(D58<>"",D58,IFERROR(E58/(IFERROR(SUM(Sales!C:C),0))*(IFERROR(SUM(Purchases!C:C),0)),0)) -> 839 | J58: =F58*I58 -> 0 | K58: =IF(LEN(G58)=0,0,G58)*I58 -> 1678 | N58: Pending | O58: L, XL
A59: CHR-58 | B59: Soft Cotton Salwar set - wine red | C59: Salwar | D59: 1145 | E59: 1500 | F59: 1 | G59: 2 | H59: =F59+IF(LEN(G59)=0,0,G59) -> 3 | I59: =IF(D59<>"",D59,IFERROR(E59/(IFERROR(SUM(Sales!C:C),0))*(IFERROR(SUM(Purchases!C:C),0)),0)) -> 1145 | J59: =F59*I59 -> 1145 | K59: =IF(LEN(G59)=0,0,G59)*I59 -> 2290 | L59: Sruthi (1300) - L | N59: Partially Sold | O59: M, XL | P59: Wine red
A60: CHR-59 | B60: Silk Blend Salwar Set | C60: Salwar | D60: 1080 | E60: 1400 | F60: 1 | G60: 1 | H60: =F60+IF(LEN(G60)=0,0,G60) -> 2 | I60: =IF(D60<>"",D60,IFERROR(E60/(IFERROR(SUM(Sales!C:C),0))*(IFERROR(SUM(Purchases!C:C),0)),0)) -> 1080 | J60: =F60*I60 -> 1080 | K60: =IF(LEN(G60)=0,0,G60)*I60 -> 1080 | L60: Jisha (XL), Rameez Relative(L): 900 | M60: Rajna | N60: Sold Out | P60: Maroon, Violet
A61: CHR-60 | B61: Imported Rayon Salwar Set | C61: Salwar | D61: 1096 | E61: 1600 | F61: 2 | G61: 4 | H61: =F61+IF(LEN(G61)=0,0,G61) -> 6 | I61: =IF(D61<>"",D61,IFERROR(E61/(IFERROR(SUM(Sales!C:C),0))*(IFERROR(SUM(Purchases!C:C),0)),0)) -> 1096 | J61: =F61*I61 -> 2192 | K61: =IF(LEN(G61)=0,0,G61)*I61 -> 4384 | L61: Deepthi - Mustard for Hokoba return | N61: Partially Sold | O61: M/XL | P61: Violet(M&XL), Pink | Q61: Peacock blue sold, grey returned
A62: CHR-61 | B62: Cotton Saree | C62: Saree | D62: 562 | E62: 750 | F62: 1 | G62: 1 | H62: =F62+IF(LEN(G62)=0,0,G62) -> 2 | I62: =IF(D62<>"",D62,IFERROR(E62/(IFERROR(SUM(Sales!C:C),0))*(IFERROR(SUM(Purchases!C:C),0)),0)) -> 562 | J62: =F62*I62 -> 562 | K62: =IF(LEN(G62)=0,0,G62)*I62 -> 562 | L62: Resmi(Tvm) - 500 | N62: Partially Sold
A63: CHR-62 | B63: Silk Saree | C63: Saree | D63: 525 | E63: 700 | F63: 1 | G63: 0 | H63: =F63+IF(LEN(G63)=0,0,G63) -> 1 | I63: =IF(D63<>"",D63,IFERROR(E63/(IFERROR(SUM(Sales!C:C),0))*(IFERROR(SUM(Purchases!C:C),0)),0)) -> 525 | J63: =F63*I63 -> 525 | K63: =IF(LEN(G63)=0,0,G63)*I63 -> 0 | L63: Dona | N63: Sold Out
A64: CHR-63 | B64: Silk Saree | C64: Saree | D64: 972 | E64: 1600 | F64: 1 | G64: 0 | H64: =F64+IF(LEN(G64)=0,0,G64) -> 1 | I64: =IF(D64<>"",D64,IFERROR(E64/(IFERROR(SUM(Sales!C:C),0))*(IFERROR(SUM(Purchases!C:C),0)),0)) -> 972 | J64: =F64*I64 -> 972 | K64: =IF(LEN(G64)=0,0,G64)*I64 -> 0 | L64: Aruna | N64: Sold Out
A65: CHR-64 | B65: Kota Linen Saree | C65: Saree | D65: 1602 | E65: 1800 | F65: 0 | G65: 1 | H65: =F65+IF(LEN(G65)=0,0,G65) -> 1 | I65: =IF(D65<>"",D65,IFERROR(E65/(IFERROR(SUM(Sales!C:C),0))*(IFERROR(SUM(Purchases!C:C),0)),0)) -> 1602 | J65: =F65*I65 -> 0 | K65: =IF(LEN(G65)=0,0,G65)*I65 -> 1602 | N65: Pending
A66: CHR-65 | B66: Mulmul Cotton Collection | C66: Saree | D66: 779 | E66: 900 | F66: 2 | G66: 2 | H66: =F66+IF(LEN(G66)=0,0,G66) -> 4 | I66: =IF(D66<>"",D66,IFERROR(E66/(IFERROR(SUM(Sales!C:C),0))*(IFERROR(SUM(Purchases!C:C),0)),0)) -> 779 | J66: =F66*I66 -> 1558 | K66: =IF(LEN(G66)=0,0,G66)*I66 -> 1558 | L66: Athulya (blued and white), Rinsha (violet & pink -850) | N66: Partially Sold
A67: CHR-66 | B67: Mul Chanderi Saree with Ajrakh Palu | C67: Saree | D67: 633 | E67: 1400 | F67: 0 | G67: 0 | H67: =F67+IF(LEN(G67)=0,0,G67) -> 0 | I67: =IF(D67<>"",D67,IFERROR(E67/(IFERROR(SUM(Sales!C:C),0))*(IFERROR(SUM(Purchases!C:C),0)),0)) -> 633 | J67: =F67*I67 -> 0 | K67: =IF(LEN(G67)=0,0,G67)*I67 -> 0 | N67: Sold Out
A68: CHR-67 | B68: Cotton Blend Saree | C68: Saree | D68: 685 | E68: 1200 | F68: 1 | G68: 1 | H68: =F68+IF(LEN(G68)=0,0,G68) -> 2 | I68: =IF(D68<>"",D68,IFERROR(E68/(IFERROR(SUM(Sales!C:C),0))*(IFERROR(SUM(Purchases!C:C),0)),0)) -> 685 | J68: =F68*I68 -> 685 | K68: =IF(LEN(G68)=0,0,G68)*I68 -> 685 | L68: Jitha Joy - 650 | N68: Partially Sold | P68: Green/Yellow available
A69: CHR-68 | B69: Soft Muslin Cotton Chridar | C69: Salwar | D69: 1700 | E69: 1700 | F69: 0 | G69: 4 | H69: =F69+IF(LEN(G69)=0,0,G69) -> 4 | I69: =IF(D69<>"",D69,IFERROR(E69/(IFERROR(SUM(Sales!C:C),0))*(IFERROR(SUM(Purchases!C:C),0)),0)) -> 1700 | J69: =F69*I69 -> 0 | K69: =IF(LEN(G69)=0,0,G69)*I69 -> 6800 | N69: Pending | O69: M-XXL
...

Sheet PartnerShares
A1: Partner Settings
A2: Partner | B2: Share %
A3: Rajna | B3: 0.3334
A4: Anoop | B4: 0.3332
A5: Rameez | B5: 0.3334
A7: Partner | B7: Total Purchases (Contributions) | C7: Target Contributions (by %) | D7: Contribution Over/(Under) | E7: Profit Share (Completed Only) | F7: Net Before Settlements | G7: Net Settlements (Received - Paid) | H7: Net Position After Settlements
A8: Rajna | B8: =IFERROR(SUMIF(Purchases!$B:$B,$A8,Purchases!$C:$C),0) -> 126654 | C8: =SUM($B$8:$B$10)/3 -> 98145.333 | D8: =B8-C8 -> 28508.667 | E8: =IF(Summary!$B$6>0, Summary!$B$6*VLOOKUP($A8,$A$3:$B$5,2,FALSE()),0) -> 0 | F8: =D8+E8 -> 28508.667 | G8: =IFERROR(SUMIFS($E$13:$E$499,$D$13:$D$499,$A8,$B$13:$B$499,"Contribution"),0)+IFERROR(SUMIFS($E$13:$E$499,$D$13:$D$499,$A8,$B$13:$B$499,"Profit"),0)-IFERROR(SUMIFS($E$13:$E$499,$C$13:$C$499,$A8,$B$13:$B$499,"Contribution"),0)-IFERROR(SUMIFS($E$13:$E$499,$C$13:$C$499,$A8,$B$13:$B$499,"Profit"),0) -> 18303.34 | H8: =F8-G8 -> 10205.327
A9: Anoop | B9: =IFERROR(SUMIF(Purchases!$B:$B,$A9,Purchases!$C:$C),0) -> 135182 | C9: =SUM($B$8:$B$10)/3 -> 98145.333 | D9: =B9-C9 -> 37036.667 | E9: =IF(Summary!$B$6>0, Summary!$B$6*VLOOKUP($A9,$A$3:$B$5,2,FALSE()),0) -> 0 | F9: =D9+E9 -> 37036.667 | G9: =IFERROR(SUMIFS($E$13:$E$499,$D$13:$D$499,$A9,$B$13:$B$499,"Contribution"),0)+IFERROR(SUMIFS($E$13:$E$499,$D$13:$D$499,$A9,$B$13:$B$499,"Profit"),0)-IFERROR(SUMIFS($E$13:$E$499,$C$13:$C$499,$A9,$B$13:$B$499,"Contribution"),0)-IFERROR(SUMIFS($E$13:$E$499,$C$13:$C$499,$A9,$B$13:$B$499,"Profit"),0) -> 41639.33 | H9: =F9-G9 -> -4602.6633
A10: Rameez | B10: =IFERROR(SUMIF(Purchases!$B:$B,$A10,Purchases!$C:$C),0) -> 32600 | C10: =SUM($B$8:$B$10)/3 -> 98145.333 | D10: =B10-C10 -> -65545.333 | E10: =IF(Summary!$B$6>0, Summary!$B$6*VLOOKUP($A10,$A$3:$B$5,2,FALSE()),0) -> 0 | F10: =D10+E10 -> -65545.333 | G10: =IFERROR(SUMIFS($E$13:$E$499,$D$13:$D$499,$A10,$B$13:$B$499,"Contribution"),0)+IFERROR(SUMIFS($E$13:$E$499,$D$13:$D$499,$A10,$B$13:$B$499,"Profit"),0)-IFERROR(SUMIFS($E$13:$E$499,$C$13:$C$499,$A10,$B$13:$B$499,"Contribution"),0)-IFERROR(SUMIFS($E$13:$E$499,$C$13:$C$499,$A10,$B$13:$B$499,"Profit"),0) -> -59942.67 | H10: =F10-G10 -> -5602.6633
A12: Global Settlements Log (used for Contributions, Cash Pool & Profit)
A13: Date | B13: Type (Contribution/Cash/Profit) | C13: From Partner | D13: To Partner | E13: Amount (₹) | F13: Notes
A14: 45952 | B14: Contribution | C14: Rameez | D14: Rajna | E14: 16032
A15: 45952 | B15: Contribution | C15: Rameez | D15: Anoop | E15: 21859
A16: 45954 | B16: Cash | C16: Rajna | D16: Rameez | E16: 28826.524
A17: 45954 | B17: Cash | C17: Rajna | D17: Anoop | E17: 32606.952
A18: 45970 | B18: Contribution | C18: Anoop | D18: Rameez | E18: 3209.34
A19: 45970 | B19: Contribution | C19: Anoop | D19: Rajna | E19: 411
A20: 45973 | B20: Contribution | C20: Anoop | D20: Rameez | E20: 905
A21: 45973 | B21: Contribution | C21: Rajna | D21: Rameez | E21: 904
A22: 46058 | B22: Contribution | C22: Rameez | D22: Anoop | E22: 27014
A23: 46059 | B23: Cash | C23: Rajna | D23: Rameez | E23: 30266
A24: 46059 | B24: Contribution | C24: Rajna | D24: Anoop | E24: 2225
A25: 46059 | B25: Cash | C25: Rajna | D25: Anoop | E25: 32354
... A29: 46093 | B29: Cash | C29: Rajna | D29: Anoop | E29: 6626.09

Sheet Cash Pool
A1: Cash Pool Overview (Completed Sales Only)
A3: Partner | B3: Cash Collected (Completed Sales) | C3: Share % | D3: Target Cash Based on % | E3: Over/(Under) Collection | F3: Net Cash Settlements (Received - Paid) | G3: Cash Position After Settlements
A4: Rajna | B4: =IFERROR(SUMIFS(Sales!$C:$C,Sales!$E:$E,$A4,Sales!$I:$I,"Completed"),0) -> 235543 | C4: =VLOOKUP($A4,PartnerShares!$A$3:$B$5,2,FALSE()) -> 0.3334 | D4: =Summary!$B$4*C4 -> 85514.433 | E4: =B4-D4 -> 150028.57 | F4: =IFERROR(SUMIFS(PartnerShares!$E$13:$E$499,PartnerShares!$D$13:$D$499,$A4,PartnerShares!$B$13:$B$499,"Cash"),0)-IFERROR(SUMIFS(PartnerShares!$E$13:$E$499,PartnerShares!$C$13:$C$499,$A4,PartnerShares!$B$13:$B$499,"Cash"),0) -> -137310.03 | G4: =E4+F4 -> 12718.541
A5: Anoop | B5: =IFERROR(SUMIFS(Sales!$C:$C,Sales!$E:$E,$A5,Sales!$I:$I,"Completed"),0) -> 8419 | C5: =VLOOKUP($A5,PartnerShares!$A$3:$B$5,2,FALSE()) -> 0.3332 | D5: =Summary!$B$4*C5 -> 85463.134 | E5: =B5-D5 -> -77044.134 | F5: =IFERROR(SUMIFS(PartnerShares!$E$13:$E$499,PartnerShares!$D$13:$D$499,$A5,PartnerShares!$B$13:$B$499,"Cash"),0)-IFERROR(SUMIFS(PartnerShares!$E$13:$E$499,PartnerShares!$C$13:$C$499,$A5,PartnerShares!$B$13:$B$499,"Cash"),0) -> 71587.042 | G5: =E5+F5 -> -5457.0924
A6: Rameez | B6: =IFERROR(SUMIFS(Sales!$C:$C,Sales!$E:$E,$A6,Sales!$I:$I,"Completed"),0) -> 12530 | C6: =VLOOKUP($A6,PartnerShares!$A$3:$B$5,2,FALSE()) -> 0.3334 | D6: =Summary!$B$4*C6 -> 85514.433 | E6: =B6-D6 -> -72984.433 | F6: =IFERROR(SUMIFS(PartnerShares!$E$13:$E$499,PartnerShares!$D$13:$D$499,$A6,PartnerShares!$B$13:$B$499,"Cash"),0)-IFERROR(SUMIFS(PartnerShares!$E$13:$E$499,PartnerShares!$C$13:$C$499,$A6,PartnerShares!$B$13:$B$499,"Cash"),0) -> 65722.984 | G6: =E6+F6 -> -7261.4488
A9: Notes:
A10: 1. Cash Collected only counts sales with Status = "Completed".
A11: 2. Target Cash is based on the same partner percentages as profit sharing.
A12: 3. Over/(Under) is the raw difference before any cash settlements.
A13: 4. Net Cash Settlements reads Type = "Cash" rows from PartnerShares Settlements Log.
A14: 5. Cash Position After Settlements = Over/(Under) + Net Cash Settlements.
